<?xml version="1.0" encoding="utf-8"?>
<robot name="armr5" xmlns:xacro="http://www.ros.org/wiki/xacro">
   <virtual_joint name="fixed_base_joint" type="fixed" parent_frame="world" child_link="base_link" />


  <xacro:include filename="aruco.urdf.xacro" />
  <link name="world"></link>
  
  <joint name="base_joint" type="fixed">
    <origin xyz="0 0 0" rpy="0 0 0"/>
    <parent link="world"/>
    <child link="base_link"/> 
  </joint>

  <!-- Base Link -->
  <link name="base_link">
    <inertial>
      <origin xyz="0.00683 0.049286 0.102411" rpy="0 0 0"/>
      <mass value="1.54609"/>
      <inertia ixx="0.00335326" ixy="-2.7434e-05" ixz="6.86595e-08" iyy="0.00381821" iyz="-1.94234e-06" izz="0.00646111"/>
    </inertial>
    <visual>
      <origin xyz="0 0 0" rpy="0 0 0"/>
      <geometry>
        <mesh filename="file:///home/chipmunk-151/Robot5A/install/robot_description/share/robot_description/meshes/base_link.STL" scale="1 1 1"/>
      </geometry>
      <material name="Gazebo/White">
        <color rgba="1 1 1 1"/>
      </material>
    </visual>
    <collision>
      <origin xyz="0 0 0" rpy="0 0 0"/>
      <geometry>
        <mesh filename="file:///home/chipmunk-151/Robot5A/install/robot_description/share/robot_description/meshes/base_link.STL" scale="1 1 1"/>
      </geometry>
    </collision>
  </link>

  <!-- Camera 1 -->
  <link name="camera_link1">
    <visual>
      <origin xyz="1.2 0 0.45" rpy="0 0 3.14159"/>
      <geometry>
        <mesh filename="file:///home/chipmunk-151/Robot5A/install/robot_description/share/robot_description/meshes/3dCamera.DAE" scale="1 1 1"/>
      </geometry>
      <material name="Gazebo/Black">
        <color rgba="0 0 0 1"/>
      </material>
    </visual>
    <collision>
      <origin xyz="1.2 0 0.45" rpy="0 0 3.14159"/>
      <geometry>
        <mesh filename="file:///home/chipmunk-151/Robot5A/install/robot_description/share/robot_description/meshes/3dCamera.DAE" scale="1 1 1"/>
      </geometry>
    </collision>
  </link>

  <!-- Joint for Camera 1 -->
  <joint name="base_to_camera1" type="fixed">
    <parent link="base_link"/>
    <child link="camera_link1"/>
    <origin xyz="1.2 0 0.45" rpy="0 0 3.14159"/>
  </joint>

  <!-- Camera 2 -->
  <link name="camera_link2">
    <visual>
      <origin xyz="-0.5 0.5 1" rpy="3.14159 0.785393 2.35619"/>
      <geometry>
        <mesh filename="file:///home/chipmunk-151/Robot5A/install/robot_description/share/robot_description/meshes/3dCamera.DAE" scale="1 1 1"/>
      </geometry>
      <material name="Gazebo/Black">
        <color rgba="0 0 0 1"/>
      </material>
    </visual>
    <collision>
      <origin xyz="-0.5 0.5 1" rpy="3.14159 0.785393 2.35619"/>
      <geometry>
        <mesh filename="file:///home/chipmunk-151/Robot5A/install/robot_description/share/robot_description/meshes/3dCamera.DAE" scale="1 1 1"/>
      </geometry>
    </collision>
  </link>

  <!-- Joint for Camera 2 -->
  <joint name="base_to_camera2" type="fixed">
    <parent link="base_link"/>
    <child link="camera_link2"/>
    <origin xyz="-0.5 0.5 1" rpy="3.14159 0.785393 2.35619"/>
  </joint>

  <!-- Gripper Left Link1 -->
  <link name="R5A_GripperLeft_Link1">
    <inertial>
      <origin xyz="-0.006595 -0.000394 2e-06" rpy="0 0 0"/>
      <mass value="0.00487858"/>
      <inertia ixx="2.28094e-07" ixy="1.69392e-08" ixz="-1.00081e-10" iyy="9.51062e-07" iyz="1.21242e-09" izz="1.15061e-06"/>
    </inertial>
    <visual>
      <origin xyz="0 0 0" rpy="0 0 0"/>
      <geometry>
        <mesh filename="file:///home/chipmunk-151/Robot5A/install/robot_description/share/robot_description/meshes/R5A_GripperLeft_Link1.STL" scale="1 1 1"/>
      </geometry>
    </visual>
    <collision>
      <origin xyz="0 0 0" rpy="0 0 0"/>
      <geometry>
        <mesh filename="file:///home/chipmunk-151/Robot5A/install/robot_description/share/robot_description/meshes/R5A_GripperLeft_Link1.STL" scale="1 1 1"/>
      </geometry>
    </collision>
  </link>

  <!-- Joint for Gripper Left Link1 -->
  <joint name="base_to_R5A_GripperLeft_Link1" type="fixed">
    <parent link="base_link"/>
    <child link="R5A_GripperLeft_Link1"/>
    <origin xyz="-0.007245 0.000392 0.842373" rpy="1.5708 0 0"/>
  </joint>

  <!-- Gripper Left Link2 -->
  <link name="R5A_GripperLeft_Link2">
    <inertial>
      <origin xyz="0.012177 0.026499 -0.000158" rpy="0 0 0"/>
      <mass value="0.0102851"/>
      <inertia ixx="3.24437e-06" ixy="-1.54511e-06" ixz="9.58012e-09" iyy="1.30527e-06" iyz="1.62739e-08" izz="3.92673e-06"/>
    </inertial>
    <visual>
      <origin xyz="0 0 0" rpy="0 0 0"/>
      <geometry>
        <mesh filename="file:///home/chipmunk-151/Robot5A/install/robot_description/share/robot_description/meshes/R5A_GripperLeft_Link2.STL" scale="1 1 1"/>
      </geometry>
    </visual>
    <collision>
      <origin xyz="0 0 0" rpy="0 0 0"/>
      <geometry>
        <mesh filename="file:///home/chipmunk-151/Robot5A/install/robot_description/share/robot_description/meshes/R5A_GripperLeft_Link2.STL" scale="1 1 1"/>
      </geometry>
    </collision>
  </link>

  <!-- Joint for Gripper Left Link2 -->
  <joint name="R5A_GripperLeft_Link1_to_R5A_GripperLeft_Link2" type="revolute">
    <parent link="R5A_GripperLeft_Link1"/>
    <child link="R5A_GripperLeft_Link2"/>
    <origin xyz="0 0 0" rpy="0 0 0"/>
    <axis xyz="0 0 1"/>
    <limit effort="5" velocity="1" lower="-1.5" upper="1.5"/>
    <dynamics damping="0.1" friction="0.0"/>
  </joint>

  <!-- Gripper Left Link3 -->
  <link name="R5A_GripperLeft_Link3">
    <inertial>
      <origin xyz="-0.02 0 0" rpy="0 0 0"/>
      <mass value="0.00167027"/>
      <inertia ixx="1.05068e-08" ixy="4.70839e-11" ixz="-2.85619e-13" iyy="3.09837e-07" iyz="5.57882e-12" izz="3.10756e-07"/>
    </inertial>
    <visual>
      <origin xyz="0 0 0" rpy="0 0 0"/>
      <geometry>
        <mesh filename="file:///home/chipmunk-151/Robot5A/install/robot_description/share/robot_description/meshes/R5A_GripperLeft_Link3.STL" scale="1 1 1"/>
      </geometry>
    </visual>
    <collision>
      <origin xyz="0 0 0" rpy="0 0 0"/>
      <geometry>
        <mesh filename="file:///home/chipmunk-151/Robot5A/install/robot_description/share/robot_description/meshes/R5A_GripperLeft_Link3.STL" scale="1 1 1"/>
      </geometry>
    </collision>
  </link>

  <!-- Joint for Gripper Left Link3 -->
  <joint name="R5A_GripperLeft_Link2_to_R5A_GripperLeft_Link3" type="revolute">
    <parent link="R5A_GripperLeft_Link2"/>
    <child link="R5A_GripperLeft_Link3"/>
    <origin xyz="0 0 0" rpy="0 0 0"/>
    <axis xyz="0 0 1"/>
    <limit effort="5" velocity="1" lower="-1.5" upper="1.5"/>
    <dynamics damping="0.1" friction="0.0"/>
  </joint>

  <!-- Gripper Right Link1 -->
  <link name="R5A_GripperRight_Link1">
    <inertial>
      <origin xyz="0.006452 -0.000421 3e-06" rpy="0 0 0"/>
      <mass value="0.00500322"/>
      <inertia ixx="2.29355e-07" ixy="-1.79692e-08" ixz="1.09051e-10" iyy="9.57608e-07" iyz="1.21375e-09" izz="1.15768e-06"/>
    </inertial>
    <visual>
      <origin xyz="0 0 0" rpy="0 0 0"/>
      <geometry>
        <mesh filename="file:///home/chipmunk-151/Robot5A/install/robot_description/share/robot_description/meshes/R5A_GripperRight_Link1.STL" scale="1 1 1"/>
      </geometry>
    </visual>
    <collision>
      <origin xyz="0 0 0" rpy="0 0 0"/>
      <geometry>
        <mesh filename="file:///home/chipmunk-151/Robot5A/install/robot_description/share/robot_description/meshes/R5A_GripperRight_Link1.STL" scale="1 1 1"/>
      </geometry>
    </collision>
  </link>

  <!-- Joint for Gripper Right Link1 -->
  <joint name="base_to_R5A_GripperRight_Link1" type="fixed">
    <parent link="base_link"/>
    <child link="R5A_GripperRight_Link1"/>
    <origin xyz="0.020755 0.000392 0.842373" rpy="1.5708 0 0"/>
  </joint>

  <!-- Gripper Right Link2 -->
  <link name="R5A_GripperRight_Link2">
    <inertial>
      <origin xyz="-0.012177 0.026499 -0.000158" rpy="0 0 0"/>
      <mass value="0.0102851"/>
      <inertia ixx="3.24437e-06" ixy="1.54511e-06" ixz="-9.56822e-09" iyy="1.30528e-06" iyz="1.63061e-08" izz="3.92673e-06"/>
    </inertial>
    <visual>
      <origin xyz="0 0 0" rpy="0 0 0"/>
      <geometry>
        <mesh filename="file:///home/chipmunk-151/Robot5A/install/robot_description/share/robot_description/meshes/R5A_GripperRight_Link2.STL" scale="1 1 1"/>
      </geometry>
    </visual>
    <collision>
      <origin xyz="0 0 0" rpy="0 0 0"/>
      <geometry>
        <mesh filename="file:///home/chipmunk-151/Robot5A/install/robot_description/share/robot_description/meshes/R5A_GripperRight_Link2.STL" scale="1 1 1"/>
      </geometry>
    </collision>
  </link>

  <!-- Joint for Gripper Right Link2 -->
  <joint name="R5A_GripperRight_Link1_to_R5A_GripperRight_Link2" type="revolute">
    <parent link="R5A_GripperRight_Link1"/>
    <child link="R5A_GripperRight_Link2"/>
    <origin xyz="0 0 0" rpy="0 0 0"/>
    <axis xyz="0 0 1"/>
    <limit effort="5" velocity="1" lower="-1.5" upper="1.5"/>
    <dynamics damping="0.1" friction="0.0"/>
  </joint>

  <!-- Gripper Right Link3 -->
  <link name="R5A_GripperRight_Link3">
    <inertial>
      <origin xyz="0.02 -4.4e-05 0" rpy="0 0 0"/>
      <mass value="0.00167027"/>
      <inertia ixx="1.05083e-08" ixy="6.53984e-10" ixz="-3.96717e-12" iyy="3.09835e-07" iyz="5.58745e-12" izz="3.10756e-07"/>
    </inertial>
    <visual>
      <origin xyz="0 0 0" rpy="0 0 0"/>
      <geometry>
        <mesh filename="file:///home/chipmunk-151/Robot5A/install/robot_description/share/robot_description/meshes/R5A_GripperRight_Link3.STL" scale="1 1 1"/>
      </geometry>
    </visual>
    <collision>
      <origin xyz="0 0 0" rpy="0 0 0"/>
      <geometry>
        <mesh filename="file:///home/chipmunk-151/Robot5A/install/robot_description/share/robot_description/meshes/R5A_GripperRight_Link3.STL" scale="1 1 1"/>
      </geometry>
    </collision>
  </link>

  <!-- Joint for Gripper Right Link3 -->
  <joint name="R5A_GripperRight_Link2_to_R5A_GripperRight_Link3" type="revolute">
    <parent link="R5A_GripperRight_Link2"/>
    <child link="R5A_GripperRight_Link3"/>
    <origin xyz="0 0 0" rpy="0 0 0"/>
    <axis xyz="0 0 1"/>
    <limit effort="5" velocity="1" lower="-1.5" upper="1.5"/>
    <dynamics damping="0.1" friction="0.0"/>
  </joint>

  <!-- R5A Link1 -->
  <link name="R5A_link1">
    <inertial>
      <origin xyz="-0.000864 0.079288 0.000217" rpy="0 0 0"/>
      <mass value="2.08661"/>
      <inertia ixx="0.00745207" ixy="4.1877e-07" ixz="-5.35083e-08" iyy="0.0069026" iyz="-7.95519e-07" izz="0.00899239"/>
    </inertial>
    <visual>
      <origin xyz="0 0 0" rpy="0 0 0"/>
      <geometry>
        <mesh filename="file:///home/chipmunk-151/Robot5A/install/robot_description/share/robot_description/meshes/R5A_link1.STL" scale="1 1 1"/>
      </geometry>
      <material name="Gazebo/White">
        <color rgba="1 1 1 1"/>
      </material>
    </visual>
    <collision>
      <origin xyz="0 0 0" rpy="0 0 0"/>
      <geometry>
        <mesh filename="file:///home/chipmunk-151/Robot5A/install/robot_description/share/robot_description/meshes/R5A_link1.STL" scale="1 1 1"/>
      </geometry>
    </collision>
  </link>

  <!-- Joint for R5A_link1 -->
  <joint name="base_to_R5A_link1" type="revolute">
    <parent link="base_link"/>
    <child link="R5A_link1"/>
    <origin xyz="0.006857 0 0.15825" rpy="1.5708 0 0"/>
    <axis xyz="0 1 0"/>
    <limit effort="5" velocity="1" lower="-1.5" upper="1.5"/>
    <dynamics damping="0.1" friction="0.0"/>
  </joint>

  <!-- R5A Link2 -->
  <link name="R5A_link2">
    <inertial>
    <origin xyz="0.00059 0.079275 -1.6e-05" rpy="0 0 0"/>
    <mass value="1.92247"/>
    <inertia ixx="0.00527703" ixy="-3.67979e-05" ixz="1.0568e-06" iyy="0.00333277" iyz="-4.85754e-08" izz="0.00543566"/>
    </inertial>
    <visual>
      <origin xyz="0 0 0" rpy="0 0 0"/>
      <geometry>
        <mesh filename="file:///home/chipmunk-151/Robot5A/install/robot_description/share/robot_description/meshes/R5A_link2.STL" scale="1 1 1"/>
      </geometry>
      <material name="Gazebo/White">
        <color rgba="1 1 1 1"/>
      </material>
    </visual>
    <collision>
      <origin xyz="0 0 0" rpy="0 0 0"/>
      <geometry>
        <mesh filename="file:///home/chipmunk-151/Robot5A/install/robot_description/share/robot_description/meshes/R5A_link2.STL" scale="1 1 1"/>
      </geometry>
    </collision>
  </link>

  <!-- Joint for R5A_link2 -->
  <joint name="R5A_link1_to_R5A_link2" type="revolute">
    <parent link="R5A_link1"/>
    <child link="R5A_link2"/>
    <origin xyz="0.003748 -1e-06 0.32375" rpy="1.5708 0 0"/>
    <axis xyz="-0.999934 0 -0.011479"/>
    <limit effort="5" velocity="1" lower="-1.5" upper="1.5"/>
    <dynamics damping="0.1" friction="0.0"/>
  </joint>

  <!-- R5A Link3 -->
  <link name="R5A_link3">
    <inertial>
      <origin xyz="-0.000316 0.042445 0.000423" rpy="0 0 0"/>
      <mass value="0.749296"/>
      <inertia ixx="0.00240427" ixy="9.17962e-06" ixz="-2.55761e-08" iyy="0.00109737" iyz="-7.84071e-06" izz="0.00236482"/>
    </inertial>
    <visual>
      <origin xyz="0 0 0" rpy="0 0 0"/>
      <geometry>
        <mesh filename="file:///home/chipmunk-151/Robot5A/install/robot_description/share/robot_description/meshes/R5A_link3.STL" scale="1 1 1"/>
      </geometry>
      <material name="Gazebo/White">
        <color rgba="1 1 1 1"/>
      </material>
    </visual>
    <collision>
      <origin xyz="0 0 0" rpy="0 0 0"/>
      <geometry>
        <mesh filename="file:///home/chipmunk-151/Robot5A/install/robot_description/share/robot_description/meshes/R5A_link3.STL" scale="1 1 1"/>
      </geometry>
    </collision>
  </link>

  <!-- Joint for R5A_link3 -->
  <joint name="R5A_link2_to_R5A_link3" type="revolute">
    <parent link="R5A_link2"/>
    <child link="R5A_link3"/>
    <origin xyz="0.006755 -1e-06 0.544874" rpy="1.5708 0 0"/>
    <axis xyz="-1 0 0"/>
    <limit effort="5" velocity="1" lower="-1.5" upper="1.5"/>
    <dynamics damping="0.1" friction="0.0"/>
  </joint>

  <!-- R5A Link4 -->
  <link name="R5A_link4">
    <inertial>
      <origin xyz="-0.000206 0.045487 -0.000219" rpy="0 0 0"/>
      <mass value="0.355081"/>
      <inertia ixx="0.00106981" ixy="-4.71992e-07" ixz="-1.57737e-07" iyy="0.000758681" iyz="-5.41943e-08" izz="0.00116812"/>
    </inertial>
    <visual>
      <origin xyz="0 0 0" rpy="0 0 0"/>
      <geometry>
        <mesh filename="file:///home/chipmunk-151/Robot5A/install/robot_description/share/robot_description/meshes/R5A_link4.STL" scale="1 1 1"/>
      </geometry>
      <material name="Gazebo/White">
        <color rgba="1 1 1 1"/>
      </material>
    </visual>
    <collision>
      <origin xyz="0 0 0" rpy="0 0 0"/>
      <geometry>
        <mesh filename="file:///home/chipmunk-151/Robot5A/install/robot_description/share/robot_description/meshes/R5A_link4.STL" scale="1 1 1"/>
      </geometry>
    </collision>
  </link>

  <!-- Joint for R5A_link4 -->
  <joint name="R5A_link3_to_R5A_link4" type="revolute">
    <parent link="R5A_link3"/>
    <child link="R5A_link4"/>
    <origin xyz="0.006755 -2e-06 0.682374" rpy="1.5708 0 0"/>
    <axis xyz="0 -0.999718 -0.023734"/>
    <limit effort="5" velocity="1" lower="-1.5" upper="1.5"/>
    <dynamics damping="0.1" friction="0.0"/>
  </joint>

  <!-- R5A Link5 -->
  <link name="R5A_link5">
    <inertial>
      <origin xyz="-0.000348 0.000167 0.013817" rpy="0 0 0"/>
      <mass value="0.198452"/>
      <inertia ixx="0.000113355" ixy="-9.16337e-08" ixz="2.545e-07" iyy="8.47212e-05" iyz="4.45439e-08" izz="6.47134e-05"/>
    </inertial>
    <visual>
      <origin xyz="0 0 0" rpy="0 0 0"/>
      <geometry>
        <mesh filename="file:///home/chipmunk-151/Robot5A/install/robot_description/share/robot_description/meshes/R5A_link5.STL" scale="1 1 1"/>
      </geometry>
      <material name="Gazebo/Black">
        <color rgba="0 0 0 1"/>
      </material>
    </visual>
    <collision>
      <origin xyz="0 0 0" rpy="0 0 0"/>
      <geometry>
        <mesh filename="file:///home/chipmunk-151/Robot5A/install/robot_description/share/robot_description/meshes/R5A_link5.STL" scale="1 1 1"/>
      </geometry>
    </collision>
  </link>

  <!-- Joint for R5A_link5 -->
  <joint name="R5A_link4_to_R5A_link5" type="revolute">
    <parent link="R5A_link4"/>
    <child link="R5A_link5"/>
    <origin xyz="0.006755 -2e-06 0.777374" rpy="0 -3e-06 -3.14159"/>
    <axis xyz="-0.995635 0.093335 0"/>
    <limit effort="5" velocity="1" lower="-1.5" upper="1.5"/>
    <dynamics damping="0.1" friction="0.0"/>
  </joint>

  <!-- Joints for the Gripper Links -->
  <joint name="GripperLeft_joint12" type="revolute">
    <parent link="R5A_GripperLeft_Link1"/>
    <child link="R5A_GripperLeft_Link2"/>
    <origin xyz="0 0 0" rpy="0 0 0"/>
    <axis xyz="0 -0.006066 -0.999982"/>
    <limit effort="5" velocity="1" lower="-1.5" upper="1.5"/>
    <dynamics damping="0.1" friction="0.0"/>
  </joint>

  <joint name="GripperLeft_joint32" type="revolute">
  <parent link="R5A_GripperLeft_Link3"/>
      <child link="R5A_GripperLeft_Link2"/>
      <origin xyz="0.007 0.02 0" rpy="0 0 0"/>
      <axis xyz="0 0.006066 0.999982"/>
      <limit effort="5" velocity="1" lower="-1.5" upper="1.5"/>
      <dynamics damping="0.1" friction="0.0"/>
    </joint>

    <joint name="GripperRight_joint12" type="revolute">
      <parent link="R5A_GripperRight_Link1"/>
      <child link="R5A_GripperRight_Link2"/>
      <origin xyz="0 0 0" rpy="0 0 0"/>
      <axis xyz="0 -0.006066 -0.999982"/>
      <limit effort="5" velocity="1" lower="-1.5" upper="1.5"/>
      <dynamics damping="0.1" friction="0.0"/>
    </joint>

    <joint name="GripperRight_joint32" type="revolute">
      <parent link="R5A_GripperRight_Link3"/>
      <child link="R5A_GripperRight_Link2"/>
      <origin xyz="-0.007 0.02 0" rpy="0 0 0"/>
      <axis xyz="0 -0.006066 -0.999982"/>
      <limit effort="5" velocity="1" lower="-1.5" upper="1.5"/>
      <dynamics damping="0.1" friction="0.0"/>
    </joint>

    <!-- Additional Joints -->
    <joint name="IdolGearB" type="revolute">
      <parent link="R5A_link5"/>
      <child link="R5A_GripperRight_Link1"/>
      <origin xyz="0 0 0" rpy="0 0 0"/>
      <axis xyz="0 -0.006066 -0.99998"/>
      <limit effort="5" velocity="1" lower="-1.5" upper="1.5"/>
      <dynamics damping="0.1" friction="0.0"/>
    </joint>

    <joint name="LeftPivotArm" type="revolute">
      <parent link="R5A_link5"/>
      <child link="R5A_GripperLeft_Link3"/>
      <origin xyz="0 0 0" rpy="0 0 0"/>
      <axis xyz="0 0.006066 0.999982"/>
      <limit effort="5" velocity="1" lower="-1.5" upper="1.5"/>
      <dynamics damping="0.1" friction="0.0"/>
    </joint>

    <joint name="R0_Yaw" type="revolute">
      <parent link="base_link"/>
      <child link="R5A_link1"/>
      <origin xyz="0 0 0" rpy="0 0 0"/>
      <axis xyz="0 1 0"/>
      <limit effort="5" velocity="1" lower="-1.5" upper="1.5"/>
      <dynamics damping="0.1" friction="0.0"/>
    </joint>

    <joint name="R1_Pitch" type="revolute">
      <parent link="R5A_link1"/>
      <child link="R5A_link2"/>
      <origin xyz="0 0 0" rpy="0 0 0"/>
      <axis xyz="-0.999934 0 -0.011479"/>
      <limit effort="5" velocity="1" lower="-1.5" upper="1.5"/>
      <dynamics damping="0.1" friction="0.0"/>
    </joint>

    <joint name="R2_Pitch" type="revolute">
      <parent link="R5A_link2"/>
      <child link="R5A_link3"/>
      <origin xyz="0 0 0" rpy="0 0 0"/>
      <axis xyz="-1 0 0"/>
      <limit effort="5" velocity="1" lower="-1.5" upper="1.5"/>
      <dynamics damping="0.1" friction="0.0"/>
    </joint>

    <joint name="R3_Yaw" type="revolute">
      <parent link="R5A_link3"/>
      <child link="R5A_link4"/>
      <origin xyz="0 0 0" rpy="0 0 0"/>
      <axis xyz="0 -0.999718 -0.023734"/>
      <limit effort="5" velocity="1" lower="-1.5" upper="1.5"/>
      <dynamics damping="0.1" friction="0.0"/>
    </joint>

    <joint name="R4_Pitch" type="revolute">
      <parent link="R5A_link4"/>
      <child link="R5A_link5"/>
      <origin xyz="0 0 0" rpy="0 0 0"/>
      <axis xyz="-0.995635 0.093335 0"/>
      <limit effort="5" velocity="1" lower="-1.5" upper="1.5"/>
      <dynamics damping="0.1" friction="0.0"/>
    </joint>

    <joint name="RightPivotArm" type="revolute">
      <parent link="R5A_link5"/>
      <child link="R5A_GripperRight_Link3"/>
      <origin xyz="0 0 0" rpy="0 0 0"/>
      <axis xyz="0 -0.006066 -0.999982"/>
      <limit effort="5" velocity="1" lower="-1.5" upper="1.5"/>
      <dynamics damping="0.1" friction="0.0"/>
    </joint>

    <joint name="ServoGearB" type="revolute">
      <parent link="R5A_link5"/>
      <child link="R5A_GripperLeft_Link1"/>
      <origin xyz="0 0 0" rpy="0 0 0"/>
      <axis xyz="0 -0.006066 -0.999982"/>
      <limit effort="5" velocity="1" lower="-1.5" upper="1.5"/>
      <dynamics damping="0.1" friction="0.0"/>
    </joint>

    <!-- Plugins -->
    <gazebo>
      <plugin name="gazebo_ros2_control" filename="libgazebo_ros2_control.so">
        <robotNamespace>/</robotNamespace>
        <robot_param>robot_description</robot_param>
        <robot_param_node>robot_state_publisher</robot_param_node>
        <robot_sim_type>gazebo_ros2_control/GazeboSystem</robot_sim_type>
        <parameters>/home/chipmunk-151/Robot5A/install/robot_description/share/robot_description/config/controller.yaml</parameters>
        <controller_manager_name>controller_manager</controller_manager_name>
        <use_sim_time>1</use_sim_time>
      </plugin>

      <plugin name="gazebo_ros_joint_pose_trajectory" filename="libgazebo_ros_joint_pose_trajectory.so">
        <update_rate>50</update_rate>
        <joint_name>R0_Yaw</joint_name>
        <joint_name>R1_Pitch</joint_name>
        <joint_name>R2_Pitch</joint_name>
        <joint_name>R3_Yaw</joint_name>
        <joint_name>R4_Pitch</joint_name>
      </plugin>
    </gazebo>
</robot>
