<?xml version="1.0"?>
<robot xmlns:xacro="http://www.ros.org/wiki/xacro">

  <link name="world"></link>

  <joint name="base_joint" type="fixed">
    <origine xyz="0 0 0" rpy="0 0 0"/>
    <parent link="world"/>
    <child link="base_link"/> 
  </joint>

  <link
    name="base_link">
    <inertial>
      <origin
        xyz="0.00683000289839214 0.0492858185856111 0.102410796188668"
        rpy="0 0 0" />
      <mass
        value="1.54608760930939" />
      <inertia
        ixx="0.00335325507409126"
        ixy="-2.74339673314697E-05"
        ixz="6.86594556641863E-08"
        iyy="0.00381821146815156"
        iyz="-1.94234209654721E-06"
        izz="0.00646111115889031" />
    </inertial>
    <visual>
      <origin
        xyz="0 0 0"
        rpy="0 0 0" />
      <geometry>
        <mesh
          filename="file://$(find robot_description)/meshes/base_link.STL" />
      </geometry>
      <material
        name="">
        <color
          rgba="0.792156862745098 0.819607843137255 0.933333333333333 1" />
      </material>
    </visual>
    <collision>
      <origin
        xyz="0 0 0"
        rpy="0 0 0" />
      <geometry>
        <mesh
          filename="file://$(find robot_description)/meshes/base_link.STL" />
      </geometry>
    </collision>
  </link>
  <link
    name="R5A_link1">
    <inertial>
      <origin
        xyz="-0.000863539879134232 0.0792884229151366 0.000217126309188392"
        rpy="0 0 0" />
      <mass
        value="2.08660345546666" />
      <inertia
        ixx="0.00705202984610834"
        ixy="4.18495769538317E-07"
        ixz="-5.35090527847856E-08"
        iyy="0.00650257727022909"
        iyz="-7.95450001919316E-07"
        izz="0.00859235014286563" />
    </inertial>
    <visual>
      <origin
        xyz="0 0 0"
        rpy="0 0 0" />
      <geometry>
        <mesh
          filename="file://$(find robot_description)/meshes/R5A_link1.STL" />
      </geometry>
      <material
        name="">
        <color
          rgba="0.792156862745098 0.819607843137255 0.933333333333333 1" />
      </material>
    </visual>
    <collision>
      <origin
        xyz="0 0 0"
        rpy="0 0 0" />
      <geometry>
        <mesh
          filename="file://$(find robot_description)/meshes/R5A_link1.STL" />
      </geometry>
    </collision>
  </link>
  <joint
    name="R0_Yaw"
    type="revolute">
    <origin
      xyz="0.00685726045199512 0 0.15825"
      rpy="1.5707963267949 0 0" />
    <parent
      link="base_link" />
    <child
      link="R5A_link1" />
    <axis
      xyz="0 1 0" />
    <limit
      lower="-1.5"
      upper="1.5"
      effort="5"
      velocity="1" />
  </joint>
  <link
    name="R5A_link2">
    <inertial>
      <origin
        xyz="0.000590340031700868 0.0792749789345379 -1.60575865215957E-05"
        rpy="0 0 0" />
      <mass
        value="1.92247082198063" />
      <inertia
        ixx="0.00487699383852878"
        ixy="-3.6797699062717E-05"
        ixz="1.05680472821036E-06"
        iyy="0.002932746016665"
        iyz="-4.85804534873411E-08"
        izz="0.00503562271238705" />
    </inertial>
    <visual>
      <origin
        xyz="0 0 0"
        rpy="0 0 0" />
      <geometry>
        <mesh
          filename="file://$(find robot_description)/meshes/R5A_link2.STL" />
      </geometry>
      <material
        name="">
        <color
          rgba="0.792156862745098 0.819607843137255 0.933333333333333 1" />
      </material>
    </visual>
    <collision>
      <origin
        xyz="0 0 0"
        rpy="0 0 0" />
      <geometry>
        <mesh
          filename="file://$(find robot_description)/meshes/R5A_link2.STL" />
      </geometry>
    </collision>
  </link>
  <joint
    name="R1_Pitch"
    type="revolute">
    <origin
      xyz="-0.00310901547925539 0.1655 0"
      rpy="0 0 0" />
    <parent
      link="R5A_link1" />
    <child
      link="R5A_link2" />
    <axis
      xyz="-1 0 0" />
    <limit
      lower="-1.5"
      upper="1.5"
      effort="5"
      velocity="1" />
  </joint>
  <link
    name="R5A_link3">
    <inertial>
      <origin
        xyz="-0.000315549279166808 0.0424449594079959 0.000423163095624355"
        rpy="0 0 0" />
      <mass
        value="0.749292336081854" />
      <inertia
        ixx="0.00200425601332893"
        ixy="9.17956375018228E-06"
        ixz="-2.55766332055333E-08"
        iyy="0.00069735819745095"
        iyz="-7.84063656624613E-06"
        izz="0.00196480563389349" />
    </inertial>
    <visual>
      <origin
        xyz="0 0 0"
        rpy="0 0 0" />
      <geometry>
        <mesh
          filename="file://$(find robot_description)/meshes/R5A_link3.STL" />
      </geometry>
      <material
        name="">
        <color
          rgba="0.792156862745098 0.819607843137255 0.933333333333333 1" />
      </material>
    </visual>
    <collision>
      <origin
        xyz="0 0 0"
        rpy="0 0 0" />
      <geometry>
        <mesh
          filename="file://$(find robot_description)/meshes/R5A_link3.STL" />
      </geometry>
    </collision>
  </link>
  <joint
    name="R2_Pitch"
    type="revolute">
    <origin
      xyz="0.00300704230231069 0.221123792803564 0"
      rpy="0 0 0" />
    <parent
      link="R5A_link2" />
    <child
      link="R5A_link3" />
    <axis
      xyz="-1 0 0" />
   <limit
      lower="-1.5"
      upper="1.5"
      effort="5"
      velocity="1" />
  </joint>
  <link
    name="R5A_link4">
    <inertial>
      <origin
        xyz="-0.000206047771173058 0.0454873904143689 -0.000219105733635074"
        rpy="0 0 0" />
      <mass
        value="0.355077243317324" />
      <inertia
        ixx="0.000669805200122677"
        ixy="-4.71996739328152E-07"
        ixz="-1.57736445618108E-07"
        iyy="0.000358674558440702"
        iyz="-5.41990969302289E-08"
        izz="0.00076811625156356" />
    </inertial>
    <visual>
      <origin
        xyz="0 0 0"
        rpy="0 0 0" />
      <geometry>
        <mesh
          filename="file://$(find robot_description)/meshes/R5A_link4.STL" />
      </geometry>
      <material
        name="">
        <color
          rgba="0.792156862745098 0.819607843137255 0.933333333333333 1" />
      </material>
    </visual>
    <collision>
      <origin
        xyz="0 0 0"
        rpy="0 0 0" />
      <geometry>
        <mesh
          filename="file://$(find robot_description)/meshes/R5A_link4.STL" />
      </geometry>
    </collision>
  </link>
  <joint
    name="R3_Yaw"
    type="revolute">
    <origin
      xyz="0 0.1375 0"
      rpy="0 0 0" />
    <parent
      link="R5A_link3" />
    <child
      link="R5A_link4" />
    <axis
      xyz="0 -1 0" />
    <limit
      lower="-1.5"
      upper="1.5"
      effort="5"
      velocity="1" />
  </joint>
  <link
    name="R5A_link5">
    <inertial>
      <origin
        xyz="-0.000304982815722917 0.000214555031841958 0.0238812711123602"
        rpy="0 0 0" />
      <mass
        value="0.232244400597819" />
      <inertia
        ixx="0.000120322215361587"
        ixy="-9.01049257248474E-08"
        ixz="2.57785604684289E-07"
        iyy="9.55044143695027E-05"
        iyz="-7.60482494086889E-08"
        izz="6.98522198363616E-05" />
    </inertial>
    <visual>
      <origin
        xyz="0 0 0"
        rpy="0 0 0" />
      <geometry>
        <mesh
          filename="file://$(find robot_description)/meshes/R5A_link5.STL" />
      </geometry>
      <material
        name="">
        <color
          rgba="1 1 1 1" />
      </material>
    </visual>
    <collision>
      <origin
        xyz="0 0 0"
        rpy="0 0 0" />
      <geometry>
        <mesh
          filename="file://$(find robot_description)/meshes/R5A_link5.STL" />
      </geometry>
    </collision>
  </link>
  <joint
    name="R4_Pitch"
    type="revolute">
    <origin
      xyz="0 0.095 0"
      rpy="1.5708 0 3.1416" />
    <parent
      link="R5A_link4" />
    <child
      link="R5A_link5" />
    <axis
      xyz="-1 0 0" />
    <limit
      lower="-1.5"
      upper="1.5"
      effort="5"
      velocity="1" />
  </joint>
    
</robot>